Workbook

Sheet Reference
A1: Pos | B1: Residues | C1: Domain
A2: 1 | B2: M1 | C2: NTD
A3: 2 | B3: F2 | C3: NTD
A4: 3 | B4: V3 | C4: NTD
A5: 4 | B5: F4 | C5: NTD
A6: 5 | B6: L5 | C6: NTD
A7: 6 | B7: V6 | C7: NTD
A8: 7 | B8: L7 | C8: NTD
A9: 8 | B9: L8 | C9: NTD
A10: 9 | B10: P9 | C10: NTD
A11: 10 | B11: L10 | C11: NTD
A12: 11 | B12: V11 | C12: NTD
A13: 12 | B13: S12 | C13: NTD
... A1274: 1273 | B1274: T1273 | C1274: S2

Sheet VOCI
A1: Mutation | B1: SAPs | C1: Variants | D1: Label | E1: Sites | F1: VarLabel | G1: Domain | H1: MonthIndex | I1: # Mutations | J1: Sites Count | K1: Mut Count | L1: Count
A2: "" | B2: "" | C2: Original | D2: Original | E2: "" | F2: Original | G2: "" | H2: 1 | I2: 0 | J2: 0 | K2: 0 | L2: 0
A3: D614G | B3: G | C3: D614G | D3: D614G | E3: 614 | F3: D614G | G3: CTD1-2 | H3: 1 | I3: =COUNTIF(F:F,F3) -> 1 | J3: =COUNTIF(E:E,E3) -> 29 | K3: =COUNTIF(A:A,A3) -> 29 | L3: =IF(J3>1,0,1) -> 0
A4: A222V | B4: V | C4: EU1(B.1.177) | D4: EU1(B.1.177) | E4: 222 | F4: EU1(B.1.177) | G4: NTD | H4: 8 | I4: =COUNTIF(F:F,F4) -> 2 | J4: =COUNTIF(E:E,E4) -> 2 | K4: =COUNTIF(A:A,A4) -> 2 | L4: =IF(J4>1,0,1) -> 0
A5: D614G | B5: G | C5: EU1(B.1.177) | D5: EU1(B.1.177) | E5: 614 | F5: EU1(B.1.177) | G5: CTD1-2 | H5: 8 | I5: =COUNTIF(F:F,F5) -> 2 | J5: =COUNTIF(E:E,E5) -> 29 | K5: =COUNTIF(A:A,A5) -> 29 | L5: =IF(J5>1,0,1) -> 0
A6: S477N | B6: N | C6: EU2(B.1.620) | D6: EU2(B.1.620) | E6: 477 | F6: EU2(B.1.620) | G6: RBD | H6: 8 | I6: =COUNTIF(F:F,F6) -> 2 | J6: =COUNTIF(E:E,E6) -> 16 | K6: =COUNTIF(A:A,A6) -> 16 | L6: =IF(J6>1,0,1) -> 0
A7: D614G | B7: G | C7: EU2(B.1.620) | D7: EU2(B.1.620) | E7: 614 | F7: EU2(B.1.620) | G7: CTD1-2 | H7: 8 | I7: =COUNTIF(F:F,F7) -> 2 | J7: =COUNTIF(E:E,E7) -> 29 | K7: =COUNTIF(A:A,A7) -> 29 | L7: =IF(J7>1,0,1) -> 0
A8: H69- | B8: - | C8: α(B.1.1.7) | D8: α(B.1.1.7) | E8: 69 | F8: B.1.1.7(Alpha) | G8: NTD | H8: 12 | I8: =COUNTIF(F:F,F8) -> 10 | J8: =COUNTIF(E:E,E8) -> 9 | K8: =COUNTIF(A:A,A8) -> 9 | L8: =IF(J8>1,0,1) -> 0
A9: V70- | B9: - | C9: α(B.1.1.7) | D9: α(B.1.1.7) | E9: 70 | F9: B.1.1.7(Alpha) | G9: NTD | H9: 12 | I9: =COUNTIF(F:F,F9) -> 10 | J9: =COUNTIF(E:E,E9) -> 9 | K9: =COUNTIF(A:A,A9) -> 9 | L9: =IF(J9>1,0,1) -> 0
A10: Y144- | B10: - | C10: α(B.1.1.7) | D10: α(B.1.1.7) | E10: 144 | F10: B.1.1.7(Alpha) | G10: NTD | H10: 12 | I10: =COUNTIF(F:F,F10) -> 10 | J10: =COUNTIF(E:E,E10) -> 13 | K10: =COUNTIF(A:A,A10) -> 12 | L10: =IF(J10>1,0,1) -> 0
A11: N501Y | B11: Y | C11: α(B.1.1.7) | D11: α(B.1.1.7) | E11: 501 | F11: B.1.1.7(Alpha) | G11: RBD | H11: 12 | I11: =COUNTIF(F:F,F11) -> 10 | J11: =COUNTIF(E:E,E11) -> 19 | K11: =COUNTIF(A:A,A11) -> 19 | L11: =IF(J11>1,0,1) -> 0
A12: A570D | B12: D | C12: α(B.1.1.7) | D12: α(B.1.1.7) | E12: 570 | F12: B.1.1.7(Alpha) | G12: CTD1-2 | H12: 12 | I12: =COUNTIF(F:F,F12) -> 10 | J12: =COUNTIF(E:E,E12) -> 5 | K12: =COUNTIF(A:A,A12) -> 1 | L12: =IF(J12>1,0,1) -> 0
A13: D614G | B13: G | C13: α(B.1.1.7) | D13: α(B.1.1.7) | E13: 614 | F13: B.1.1.7(Alpha) | G13: CTD1-2 | H13: 12 | I13: =COUNTIF(F:F,F13) -> 10 | J13: =COUNTIF(E:E,E13) -> 29 | K13: =COUNTIF(A:A,A13) -> 29 | L13: =IF(J13>1,0,1) -> 0
A14: P681H | B14: H | C14: α(B.1.1.7) | D14: α(B.1.1.7) | E14: 681 | F14: B.1.1.7(Alpha) | G14: CTD1-2 | H14: 12 | I14: =COUNTIF(F:F,F14) -> 10 | J14: =COUNTIF(E:E,E14) -> 20 | K14: =COUNTIF(A:A,A14) -> 13 | L14: =IF(J14>1,0,1) -> 0
... A777: P1143L | B777: L | C777: KP.3 | D777: KP.3 | E777: 1143 | F777: KP.3 | G777: S2 | H777: 53 | I777: =COUNTIF(F:F,F777) -> 63 | J777: =COUNTIF(E:E,E777) -> 4 | K777: =COUNTIF(A:A,A777) -> 4 | L777: =IF(J777>1,0,1) -> 0

Sheet Sheet2
A1: Mutation | B1: SAPs | C1: Variants | D1: Sites | E1: Variants | F1: Domain | G1: MonthIndex | H1: # Mutations | K1: Amino Acids | L1: Nucleotides | M1: Codons
A2: "" | B2: "" | C2: Original | D2: "" | E2: Original | F2: "" | G2: 1 | H2: 0 | K2: "" | L2: ""
A3: D614G | B3: G | C3: D614G | D3: 614 | E3: D614G | F3: CTD1-2 | G3: 1 | H3: =COUNTIF(E:E,E3) -> 1 | K3: D614G | L3: A1841G | M3: GAT614GGT
A4: A222V | B4: V | C4: EU1(B.1.177) | D4: 222 | E4: EU1(B.1.177) | F4: NTD | G4: 8 | H4: =COUNTIF(E:E,E4) -> 2 | K4: A222V | L4: C665T
A5: D614G | B5: G | C5: EU1(B.1.177) | D5: 614 | E5: EU1(B.1.177) | F5: CTD1-2 | G5: 8 | H5: =COUNTIF(E:E,E5) -> 2 | K5: S477N | L5: G1430A
A6: S477N | B6: N | C6: EU2(B.1.620) | D6: 477 | E6: EU2(B.1.620) | F6: RBD | G6: 8 | H6: =COUNTIF(E:E,E6) -> 2 | K6: H69- | L6: T203-;A204-;C205-
A7: D614G | B7: G | C7: EU2(B.1.620) | D7: 614 | E7: EU2(B.1.620) | F7: CTD1-2 | G7: 8 | H7: =COUNTIF(E:E,E7) -> 2 | K7: V70- | L7: A206-;T207-;G208-
A8: H69- | B8: - | C8: α(B.1.1.7) | D8: 69 | E8: B.1.1.7(Alpha) | F8: NTD | G8: 12 | H8: =COUNTIF(E:E,E8) -> 10 | K8: Y144- | L8: T430-;A431-;T432-
A9: V70- | B9: - | C9: α(B.1.1.7) | D9: 70 | E9: B.1.1.7(Alpha) | F9: NTD | G9: 12 | H9: =COUNTIF(E:E,E9) -> 10 | K9: N501Y | L9: A1501T
A10: Y144- | B10: - | C10: α(B.1.1.7) | D10: 144 | E10: B.1.1.7(Alpha) | F10: NTD | G10: 12 | H10: =COUNTIF(E:E,E10) -> 10 | K10: A570D | L10: C1709A
A11: N501Y | B11: Y | C11: α(B.1.1.7) | D11: 501 | E11: B.1.1.7(Alpha) | F11: RBD | G11: 12 | H11: =COUNTIF(E:E,E11) -> 10 | K11: P681H | L11: C2042A
A12: A570D | B12: D | C12: α(B.1.1.7) | D12: 570 | E12: B.1.1.7(Alpha) | F12: CTD1-2 | G12: 12 | H12: =COUNTIF(E:E,E12) -> 10 | K12: T716I | L12: C2147T
A13: D614G | B13: G | C13: α(B.1.1.7) | D13: 614 | E13: B.1.1.7(Alpha) | F13: CTD1-2 | G13: 12 | H13: =COUNTIF(E:E,E13) -> 10 | K13: S982A | L13: T2944G
A14: P681H | B14: H | C14: α(B.1.1.7) | D14: 681 | E14: B.1.1.7(Alpha) | F14: CTD1-2 | G14: 12 | H14: =COUNTIF(E:E,E14) -> 10 | K14: D1118H | L14: G3352C
A15: T716I | B15: I | C15: α(B.1.1.7) | D15: 716 | E15: B.1.1.7(Alpha) | F15: S2 | G15: 12 | H15: =COUNTIF(E:E,E15) -> 10 | K15: L18F | L15: C52T
... A61: D950N | B61: N | C61: 21I Delta | D61: 950 | E61: 21I Delta | F61: S2 | G61: 18 | H61: =COUNTIF(E:E,E61) -> 11 | K61: G252- | L61: G755-;T756-;G757-
A62: E154K | B62: K | C62: κ(B.1.617.1) | D62: 154 | E62: κ(B.1.617.1) | F62: NTD | G62: 15 | H62: =COUNTIF(E:E,E62) -> 6 | K62: D253N | L62: #N/A
A63: L452R | B63: R | C63: κ(B.1.617.1) | D63: 452 | E63: κ(B.1.617.1) | F63: RBD | G63: 15 | H63: =COUNTIF(E:E,E63) -> 6 | K63: L452Q | L63: T1355A
A64: E484Q | B64: Q | C64: κ(B.1.617.1) | D64: 484 | E64: κ(B.1.617.1) | F64: RBD | G64: 15 | H64: =COUNTIF(E:E,E64) -> 6 | K64: F490S | L64: T1469C
A65: D614G | B65: G | C65: κ(B.1.617.1) | D65: 614 | E65: κ(B.1.617.1) | F65: CTD1-2 | G65: 15 | H65: =COUNTIF(E:E,E65) -> 6 | K65: T859N | L65: C2576A
A66: P681R | B66: R | C66: κ(B.1.617.1) | D66: 681 | E66: κ(B.1.617.1) | F66: CTD1-2 | G66: 15 | H66: =COUNTIF(E:E,E66) -> 6 | K66: Y144S | L66: A431C
A67: Q1071H | B67: H | C67: κ(B.1.617.1) | D67: 1071 | E67: κ(B.1.617.1) | F67: S2 | G67: 15 | H67: =COUNTIF(E:E,E67) -> 6 | K67: Y145N | L67: T433A
A68: S13I | B68: I | C68: ε(B.1.427,B.1.429) | D68: 13 | E68: 21C Epsilon | F68: NTD | G68: 12 | H68: =COUNTIF(E:E,E68) -> 4 | K68: R346K | L68: G1037A
A69: W152C | B69: C | C69: ε(B.1.427,B.1.429) | D69: 152 | E69: 21C Epsilon | F69: NTD | G69: 12 | H69: =COUNTIF(E:E,E69) -> 4 | K69: G142- | L69: G425-;T426-;G427-
A70: L452R | B70: R | C70: ε(B.1.427,B.1.429) | D70: 452 | E70: 21C Epsilon | F70: RBD | G70: 12 | H70: =COUNTIF(E:E,E70) -> 4 | K70: V143- | L70: T428-;T429-;T430-
A71: D614G | B71: G | C71: ε(B.1.427,B.1.429) | D71: 614 | E71: 21C Epsilon | F71: CTD1-2 | G71: 12 | H71: =COUNTIF(E:E,E71) -> 4 | K71: Y145D | L71: ?
A72: Q52R | B72: R | C72: η(B.1.525) | D72: 52 | E72: B.1.525(Eta) | F72: NTD | G72: 15 | H72: =COUNTIF(E:E,E72) -> 9 | K72: N211- | L72: A632-;T633-;T634-
A73: A67V | B73: V | C73: η(B.1.525) | D73: 67 | E73: B.1.525(Eta) | F73: NTD | G73: 15 | H73: =COUNTIF(E:E,E73) -> 9 | K73: L212I | L73: ?
A74: H69- | B74: - | C74: η(B.1.525) | D74: 69 | E74: B.1.525(Eta) | F74: NTD | G74: 15 | H74: =COUNTIF(E:E,E74) -> 9 | K74: G339D | L74: G1016A
... A104: R346K | B104: K | C104: μ(B.1.621) | D104: 346 | E104: B.1.621(Mu) | F104: RBD | G104: 17 | H104: =COUNTIF(E:E,E104) -> 9 | K104: S704L | L104: C2111T
A105: E484K | B105: K | C105: μ(B.1.621) | D105: 484 | E105: B.1.621(Mu) | F105: RBD | G105: 17 | H105: =COUNTIF(E:E,E105) -> 9 | K105: K147E | L105: #N/A
A106: N501Y | B106: Y | C106: μ(B.1.621) | D106: 501 | E106: B.1.621(Mu) | F106: RBD | G106: 17 | H106: =COUNTIF(E:E,E106) -> 9 | K106: W152R | L106: #N/A
A107: D614G | B107: G | C107: μ(B.1.621) | D107: 614 | E107: B.1.621(Mu) | F107: CTD1-2 | G107: 17 | H107: =COUNTIF(E:E,E107) -> 9 | K107: F157L | L107: #N/A
A108: P681H | B108: H | C108: μ(B.1.621) | D108: 681 | E108: B.1.621(Mu) | F108: CTD1-2 | G108: 17 | H108: =COUNTIF(E:E,E108) -> 9 | K108: I210V | L108: #N/A
A109: D950N | B109: N | C109: μ(B.1.621) | D109: 950 | E109: B.1.621(Mu) | F109: S2 | G109: 17 | H109: =COUNTIF(E:E,E109) -> 9 | K109: G257S | L109: #N/A
A110: A67V | B110: V | C110: BA.1 | D110: 67 | E110: BA.1 | F110: NTD | G110: 23 | H110: =COUNTIF(E:E,E110) -> 36 | K110: G339H | L110: #N/A
A111: H69- | B111: - | C111: BA.1 | D111: 69 | E111: BA.1 | F111: NTD | G111: 23 | H111: =COUNTIF(E:E,E111) -> 36 | K111: N460K | L111: #N/A
A112: V70- | B112: - | C112: BA.1 | D112: 70 | E112: BA.1 | F112: NTD | G112: 23 | H112: =COUNTIF(E:E,E112) -> 36 | K112: K444T | L112: #N/A
A113: T95I | B113: I | C113: BA.1 | D113: 95 | E113: BA.1 | F113: NTD | G113: 23 | H113: =COUNTIF(E:E,E113) -> 36 | K113: Q493Q | L113: #N/A
A114: G142- | B114: - | C114: BA.1 | D114: 142 | E114: BA.1 | F114: NTD | G114: 23 | H114: =COUNTIF(E:E,E114) -> 36 | K114: V83A | L114: #N/A
...

Sheet Sheet1
A1: Mutation | B1: VarLabel | C1: Sites | D1: Domain | E1: Mutated | F1: Native | G1: Delta_Hydropathycity | H1: Delta_Polarity | I1: Delta_Bulkiness
A2: H69- | B2: B.1.1.7(Alpha) | C2: 69 | D2: NTD | E2: - | F2: H | G2: =VLOOKUP($E2,'AA-List'!$B:C,2,0)-VLOOKUP($F2,'AA-List'!$B:C,2,0) -> #N/A | H2: =VLOOKUP($E2,'AA-List'!$B:D,3,0)-VLOOKUP($F2,'AA-List'!$B:D,3,0) -> #N/A | I2: =VLOOKUP($E2,'AA-List'!$B:E,4,0)-VLOOKUP($F2,'AA-List'!$B:E,4,0) -> #N/A
A3: V70- | B3: B.1.1.7(Alpha) | C3: 70 | D3: NTD | E3: - | F3: V | G3: =VLOOKUP($E3,'AA-List'!$B:C,2,0)-VLOOKUP($F3,'AA-List'!$B:C,2,0) -> #N/A | H3: =VLOOKUP($E3,'AA-List'!$B:D,3,0)-VLOOKUP($F3,'AA-List'!$B:D,3,0) -> #N/A | I3: =VLOOKUP($E3,'AA-List'!$B:E,4,0)-VLOOKUP($F3,'AA-List'!$B:E,4,0) -> #N/A
A4: Y144- | B4: B.1.1.7(Alpha) | C4: 144 | D4: NTD | E4: - | F4: Y | G4: =VLOOKUP($E4,'AA-List'!$B:C,2,0)-VLOOKUP($F4,'AA-List'!$B:C,2,0) -> #N/A | H4: =VLOOKUP($E4,'AA-List'!$B:D,3,0)-VLOOKUP($F4,'AA-List'!$B:D,3,0) -> #N/A | I4: =VLOOKUP($E4,'AA-List'!$B:E,4,0)-VLOOKUP($F4,'AA-List'!$B:E,4,0) -> #N/A
A5: N501Y | B5: B.1.1.7(Alpha) | C5: 501 | D5: RBD | E5: Y | F5: N | G5: =VLOOKUP($E5,'AA-List'!$B:C,2,0)-VLOOKUP($F5,'AA-List'!$B:C,2,0) -> 2.2 | H5: =VLOOKUP($E5,'AA-List'!$B:D,3,0)-VLOOKUP($F5,'AA-List'!$B:D,3,0) -> -5.4 | I5: =VLOOKUP($E5,'AA-List'!$B:E,4,0)-VLOOKUP($F5,'AA-List'!$B:E,4,0) -> 5.21
A6: A570D | B6: B.1.1.7(Alpha) | C6: 570 | D6: CTD1-2 | E6: D | F6: A | G6: =VLOOKUP($E6,'AA-List'!$B:C,2,0)-VLOOKUP($F6,'AA-List'!$B:C,2,0) -> -5.3 | H6: =VLOOKUP($E6,'AA-List'!$B:D,3,0)-VLOOKUP($F6,'AA-List'!$B:D,3,0) -> 4.9 | I6: =VLOOKUP($E6,'AA-List'!$B:E,4,0)-VLOOKUP($F6,'AA-List'!$B:E,4,0) -> 0.18
A7: D614G | B7: B.1.1.7(Alpha) | C7: 614 | D7: CTD1-2 | E7: G | F7: D | G7: =VLOOKUP($E7,'AA-List'!$B:C,2,0)-VLOOKUP($F7,'AA-List'!$B:C,2,0) -> 3.1 | H7: =VLOOKUP($E7,'AA-List'!$B:D,3,0)-VLOOKUP($F7,'AA-List'!$B:D,3,0) -> -4 | I7: =VLOOKUP($E7,'AA-List'!$B:E,4,0)-VLOOKUP($F7,'AA-List'!$B:E,4,0) -> -8.28
A8: P681H | B8: B.1.1.7(Alpha) | C8: 681 | D8: CTD1-2 | E8: H | F8: P | G8: =VLOOKUP($E8,'AA-List'!$B:C,2,0)-VLOOKUP($F8,'AA-List'!$B:C,2,0) -> -1.6 | H8: =VLOOKUP($E8,'AA-List'!$B:D,3,0)-VLOOKUP($F8,'AA-List'!$B:D,3,0) -> 2.4 | I8: =VLOOKUP($E8,'AA-List'!$B:E,4,0)-VLOOKUP($F8,'AA-List'!$B:E,4,0) -> -3.74
A9: T716I | B9: B.1.1.7(Alpha) | C9: 716 | D9: S2 | E9: I | F9: T | G9: =VLOOKUP($E9,'AA-List'!$B:C,2,0)-VLOOKUP($F9,'AA-List'!$B:C,2,0) -> 5.2 | H9: =VLOOKUP($E9,'AA-List'!$B:D,3,0)-VLOOKUP($F9,'AA-List'!$B:D,3,0) -> -3.4 | I9: =VLOOKUP($E9,'AA-List'!$B:E,4,0)-VLOOKUP($F9,'AA-List'!$B:E,4,0) -> 5.63
A10: S982A | B10: B.1.1.7(Alpha) | C10: 982 | D10: S2 | E10: A | F10: S | G10: =VLOOKUP($E10,'AA-List'!$B:C,2,0)-VLOOKUP($F10,'AA-List'!$B:C,2,0) -> 2.6 | H10: =VLOOKUP($E10,'AA-List'!$B:D,3,0)-VLOOKUP($F10,'AA-List'!$B:D,3,0) -> -1.1 | I10: =VLOOKUP($E10,'AA-List'!$B:E,4,0)-VLOOKUP($F10,'AA-List'!$B:E,4,0) -> 2.03
A11: D1118H | B11: B.1.1.7(Alpha) | C11: 1118 | D11: S2 | E11: H | F11: D | G11: =VLOOKUP($E11,'AA-List'!$B:C,2,0)-VLOOKUP($F11,'AA-List'!$B:C,2,0) -> 0.3 | H11: =VLOOKUP($E11,'AA-List'!$B:D,3,0)-VLOOKUP($F11,'AA-List'!$B:D,3,0) -> -2.6 | I11: =VLOOKUP($E11,'AA-List'!$B:E,4,0)-VLOOKUP($F11,'AA-List'!$B:E,4,0) -> 2.01
A12: L18F | B12: B.1.351(Beta) | C12: 18 | D12: NTD | E12: F | F12: L | G12: =VLOOKUP($E12,'AA-List'!$B:C,2,0)-VLOOKUP($F12,'AA-List'!$B:C,2,0) -> -1 | H12: =VLOOKUP($E12,'AA-List'!$B:D,3,0)-VLOOKUP($F12,'AA-List'!$B:D,3,0) -> 0.3 | I12: =VLOOKUP($E12,'AA-List'!$B:E,4,0)-VLOOKUP($F12,'AA-List'!$B:E,4,0) -> -1.6
A13: D80A | B13: B.1.351(Beta) | C13: 80 | D13: NTD | E13: A | F13: D | G13: =VLOOKUP($E13,'AA-List'!$B:C,2,0)-VLOOKUP($F13,'AA-List'!$B:C,2,0) -> 5.3 | H13: =VLOOKUP($E13,'AA-List'!$B:D,3,0)-VLOOKUP($F13,'AA-List'!$B:D,3,0) -> -4.9 | I13: =VLOOKUP($E13,'AA-List'!$B:E,4,0)-VLOOKUP($F13,'AA-List'!$B:E,4,0) -> -0.18
... A764: P1143L | B764: KP.3 | C764: 1143 | D764: S2 | E764: L | F764: P | G764: =VLOOKUP($E764,'AA-List'!$B:C,2,0)-VLOOKUP($F764,'AA-List'!$B:C,2,0) -> 5.4 | H764: =VLOOKUP($E764,'AA-List'!$B:D,3,0)-VLOOKUP($F764,'AA-List'!$B:D,3,0) -> -3.1 | I764: =VLOOKUP($E764,'AA-List'!$B:E,4,0)-VLOOKUP($F764,'AA-List'!$B:E,4,0) -> 3.97

Sheet AA-List
A1: Amino Acid | B1: AA | C1: Hydropathicity | D1: Polarity | E1: Bulkiness | H1: Mutation | M1: VarLabel
A2: Ala | B2: A | C2: 1.8 | D2: 8.1 | E2: 11.5 | H2: L5F | I2: =INT(MID(H2,2,LEN(H2)-2)) -> 5 | K2: 5 | M2: B.1.1.7(Alpha)
A3: Arg | B3: R | C3: -4.5 | D3: 10.5 | E3: 14.28 | H3: S13I | I3: =INT(MID(H3,2,LEN(H3)-2)) -> 13 | K3: 13 | M3: B.1.351(Beta)
A4: Asn | B4: N | C4: -3.5 | D4: 11.6 | E4: 12.82 | H4: L18F | I4: =INT(MID(H4,2,LEN(H4)-2)) -> 18 | K4: 18 | M4: P.1(Gamma)
A5: Asp | B5: D | C5: -3.5 | D5: 13 | E5: 11.68 | H5: T19R | I5: =INT(MID(H5,2,LEN(H5)-2)) -> 19 | K5: 19 | M5: B.1.617.2(Delta)
A6: Cys | B6: C | C6: 2.5 | D6: 5.5 | E6: 13.46 | H6: T19I | I6: =INT(MID(H6,2,LEN(H6)-2)) -> 19 | K6: 20 | M6: κ(B.1.617.1)
A7: Gln | B7: Q | C7: -3.5 | D7: 10.5 | E7: 14.45 | H7: T20N | I7: =INT(MID(H7,2,LEN(H7)-2)) -> 20 | K7: 21 | M7: 21C Epsilon
A8: Glu | B8: E | C8: -3.5 | D8: 12.3 | E8: 13.57 | H8: R21T | I8: =INT(MID(H8,2,LEN(H8)-2)) -> 21 | K8: 26 | M8: B.1.525(Eta)
A9: Gly | B9: G | C9: -0.4 | D9: 9 | E9: 3.4 | H9: P26S | I9: =INT(MID(H9,2,LEN(H9)-2)) -> 26 | K9: 27 | M9: B.1.526(Iota)
A10: His | B10: H | C10: -3.2 | D10: 10.4 | E10: 13.69 | H10: A27S | I10: =INT(MID(H10,2,LEN(H10)-2)) -> 27 | K10: 50 | M10: C.37(Lambda)
A11: Ile | B11: I | C11: 4.5 | D11: 5.2 | E11: 21.4 | H11: S50L | I11: =INT(MID(H11,2,LEN(H11)-2)) -> 50 | K11: 52 | M11: B.1.621(Mu)
A12: Leu | B12: L | C12: 3.8 | D12: 4.9 | E12: 21.4 | H12: Q52R | I12: =INT(MID(H12,2,LEN(H12)-2)) -> 52 | K12: 67 | M12: EU1(B.1.177)
A13: Lys | B13: K | C13: -3.9 | D13: 11.3 | E13: 15.71 | H13: Q52H | I13: =INT(MID(H13,2,LEN(H13)-2)) -> 52 | K13: 75 | M13: EU2(B.1.620)
... A21: Val | B21: V | C21: 4.2 | D21: 5.9 | E21: 21.57 | H21: D138Y | I21: =INT(MID(H21,2,LEN(H21)-2)) -> 138 | K21: 144 | M21: XBB.1.5
H22: G142D | I22: =INT(MID(H22,2,LEN(H22)-2)) -> 142 | K22: 145 | M22: XBB.1.16
H23: Y144S | I23: =INT(MID(H23,2,LEN(H23)-2)) -> 144 | K23: 146 | M23: EG.5.1
H24: Y145N | I24: =INT(MID(H24,2,LEN(H24)-2)) -> 145 | K24: 147 | M24: BA.2.86
H25: Y145D | I25: =INT(MID(H25,2,LEN(H25)-2)) -> 145 | K25: 152 | M25: JN.1
H26: H146Q | I26: =INT(MID(H26,2,LEN(H26)-2)) -> 146 | K26: 154 | M26: HK.3
H27: K147E | I27: =INT(MID(H27,2,LEN(H27)-2)) -> 147 | K27: 157 | M27: KP.2
H28: W152C | I28: =INT(MID(H28,2,LEN(H28)-2)) -> 152 | K28: 158 | M28: KP.3
H29: W152R | I29: =INT(MID(H29,2,LEN(H29)-2)) -> 152 | K29: 180
H30: E154K | I30: =INT(MID(H30,2,LEN(H30)-2)) -> 154 | K30: 183
H31: F157L | I31: =INT(MID(H31,2,LEN(H31)-2)) -> 157 | K31: 190
H32: F157S | I32: =INT(MID(H32,2,LEN(H32)-2)) -> 157 | K32: 210
H33: R158G | I33: =INT(MID(H33,2,LEN(H33)-2)) -> 158 | K33: 212
H34: E180V | I34: =INT(MID(H34,2,LEN(H34)-2)) -> 180 | K34: 213
H35: Q183E | I35: =INT(MID(H35,2,LEN(H35)-2)) -> 183 | K35: 215
H36: R190S | I36: =INT(MID(H36,2,LEN(H36)-2)) -> 190 | K36: 216
H37: I210V | I37: =INT(MID(H37,2,LEN(H37)-2)) -> 210 | K37: 222
H38: L212I | I38: =INT(MID(H38,2,LEN(H38)-2)) -> 212 | K38: 245
H39: V213G | I39: =INT(MID(H39,2,LEN(H39)-2)) -> 213 | K39: 252
H40: V213E | I40: =INT(MID(H40,2,LEN(H40)-2)) -> 213 | K40: 253
... H104: H655Y | I104: =INT(MID(H104,2,LEN(H104)-2)) -> 655 | K104: 1176
H105: Q677H | I105: =INT(MID(H105,2,LEN(H105)-2)) -> 677
H106: N679K | I106: =INT(MID(H106,2,LEN(H106)-2)) -> 679
H107: P681H | I107: =INT(MID(H107,2,LEN(H107)-2)) -> 681
H108: P681R | I108: =INT(MID(H108,2,LEN(H108)-2)) -> 681
H109: A701V | I109: =INT(MID(H109,2,LEN(H109)-2)) -> 701
H110: S704L | I110: =INT(MID(H110,2,LEN(H110)-2)) -> 704
...

Sheet MutRef
A1: mutation | B1: clades | C1: class | D1: mutation info|insertion info
A2: "" | B2: Original | C2: Original | D2: ""|""
A3: A1841G | B3: D614G | C3: D614G | D3: D614G|""
A4: C665T;A1841G | B4: EU1(B.1.177) | C4: EU1(B.1.177) | D4: A222V;D614G|""
A5: G1430A;A1841G | B5: EU2(B.1.620) | C5: EU2(B.1.620) | D5: S477N;D614G|""
A6: T203-;A204-;C205-;A206-;T207-;G208-;T430-;A431-;T432-;A1501T;C1709A;A1841G;C2042A;C2147T;T2944G;G3352C | B6: 20I (Alpha, V1) | C6: B.1.1.7(Alpha) | D6: H69-;V70-;Y144-;N501Y;A570D;D614G;P681H;T716I;S982A;D1118H|""
A7: T722-;A723-;C724-;T725-;T726-;G727-;C728-;T729-;T730-;C52T;A239C;A644G;G1251T;G1450A;A1501T;A1841G;C2102T | B7: 20H (Beta, V2) | C7: B.1.351(Beta) | D7: L18F;D80A;D215G;L241-;L242-;A243-;K417N;E484K;N501Y;D614G;A701V|""
A8: C52T;C59A;C76T;G412T;G570T;A1250C;G1450A;A1501T;A1841G;C1963T;C3080T;G3526T | B8: 20J (Gamma, V3) | C8: P.1(Gamma) | D8: L18F;T20N;P26S;D138Y;R190S;K417T;E484K;N501Y;D614G;H655Y;T1027I;V1176F|""
A9: A467-;G468-;T469-;T470-;C471-;A472-;C56G;G425A;T1355G;C1433A;A1841G;C2042G;G2848A | B9: 21A (Delta) | C9: B.1.617.2(Delta) | D9: T19R;G142D;E156-;F157-;R158G;L452R;T478K;D614G;P681R;D950N|""
A10: A467-;G468-;T469-;T470-;C471-;A472-;C56G;G425A;C665T;T1355G;C1433A;A1841G;C2042G;G2848A | B10: 21I (Delta) | C10: 21I Delta | D10: T19R;G142D;E156-;F157-;R158G;A222V;L452R;T478K;D614G;P681R;D950N|""
A11: G460A;T1355G;G1450C;A1841G;C2042G;A3213T | B11: 21B (Kappa) | C11: B.1.617.1(Kappa) | D11: E154K;L452R;E484Q;D614G;P681R;Q1071H|""
A12: T203-;A204-;C205-;A206-;T207-;G208-;T430-;A431-;T432-;A155G;C200T;G1450A;A1841G;G2031C;T2662C | B12: 21D (Eta) | C12: B.1.525(Eta) | D12: Q52R;A67V;H69-;V70-;Y144-;E484K;D614G;Q677H;F888L|""
... A31: C56T;C60T;G62C;T71-;A72-;C73-;C74-;C75-;C76-;C77-;T78-;G79-;C149T;T203-;A204-;C205-;A206-;T207-;G208-;G379T;G425A;T430-;A431-;T432-;T470C;C471A;A472G;A632-;T633-;T634-;T638G;C646T;C733A;C791A;A994G;G1015C;G1016A;A1067C;C1112T;T1117C;C1124T;A1126G;G1208A;G1213A;A1224C;G1251T;T1320G;G1333C;T1334A;G1336A;A1348G;C1354T;T1355G;T1364C;T1366C;T1380A;G1430A;C1433A;T1443A;G1447A;T1448-;T1449-;G1450-;T1456C;T1457C;C1477G;A1493G;A1501T;T1513C;G1660A;C1709T;A1841G;C1861T;C1963T;T2037G;C2042G;C2292A;G2386T;C2816T;A2862T;T2907A;G3310T;C3428T;C3438T;C3645T | B31: 24C (Omicron) | C31: KP.3 | D31: T19I;R21T;L24-;P25-;P26-;A27S;S50L;H69-;V70-;V127F;G142D;Y144-;F157S;R158G;N211-;L212I;V213G;L216F;H245N;A264D;I332V;G339H;K356T;S371F;S373P;S375F;T376A;R403K;D405N;R408S;K417N;N440K;V445H;G446S;N450D;L452W;L455S;F456L;N460K;S477N;T478K;N481K;V483-;E484K;F486P;Q493E;Q498R;N501Y;Y505H;E554K;A570V;D614G;P621S;H655Y;N679K;P681R;N764K;D796Y;S939F;Q954H;N969K;V1104L;P1143L|""

Sheet NT_VOCI
A1: Nt_Mutation | B1: class | C1: MonthIndex | D1: clades | E1: Mutation | F1: VarLabel
A2: "" | B2: Original | C2: 1 | D2: Original | E2: "" | F2: Original
A3: A1841G | B3: D614G | C3: 1 | D3: D614G | E3: A1841G | F3: D614G
A4: C665T | B4: EU1(B.1.177) | C4: 8 | D4: EU1(B.1.177) | E4: C665T | F4: EU1(B.1.177)
A5: A1841G | B5: EU1(B.1.177) | C5: 8 | D5: EU1(B.1.177) | E5: A1841G | F5: EU1(B.1.177)
A6: G1430A | B6: EU2(B.1.620) | C6: 8 | D6: EU2(B.1.620) | E6: G1430A | F6: EU2(B.1.620)
A7: A1841G | B7: EU2(B.1.620) | C7: 8 | D7: EU2(B.1.620) | E7: A1841G | F7: EU2(B.1.620)
A8: T203-;A204-;C205- | B8: B.1.1.7(Alpha) | C8: 9 | D8: 20I (Alpha, V1) | E8: T203-;A204-;C205- | F8: B.1.1.7(Alpha)
A9: A206-;T207-;G208- | B9: B.1.1.7(Alpha) | C9: 9 | D9: 20I (Alpha, V1) | E9: A206-;T207-;G208- | F9: B.1.1.7(Alpha)
A10: T430-;A431-;T432- | B10: B.1.1.7(Alpha) | C10: 9 | D10: 20I (Alpha, V1) | E10: T430-;A431-;T432- | F10: B.1.1.7(Alpha)
A11: A1501T | B11: B.1.1.7(Alpha) | C11: 9 | D11: 20I (Alpha, V1) | E11: A1501T | F11: B.1.1.7(Alpha)
A12: C1709A | B12: B.1.1.7(Alpha) | C12: 9 | D12: 20I (Alpha, V1) | E12: C1709A | F12: B.1.1.7(Alpha)
A13: A1841G | B13: B.1.1.7(Alpha) | C13: 9 | D13: 20I (Alpha, V1) | E13: A1841G | F13: B.1.1.7(Alpha)
... A882: C3645T | B882: KP.3 | C882: 53 | D882: 24C (Omicron) | E882: C3645T | F882: KP.3

Sheet AA TO NT
A1: Mutation | B1: SAPs | C1: Variants | D1: Label | E1: Sites | F1: S_gene_1 | G1: S_gene_2 | H1: S_gene_3 | I1: gene_1 | J1: gene_2 | K1: gene_3 | L1: VarLabel | M1: Domain | N1: MonthIndex | O1: # Mutations | P1: Sites Count | Q1: Mut Count | R1: Count | T1: Nt_Mutation | U1: class | V1: MonthIndex | W1: clades | X1: Mutation | Y1: VarLabel | AA1: MonthIndex | AB1: VarLabel
A2: T19I | B2: I | C2: EG.5.1 | D2: EG.5.1 | E2: 19 | F2: 55 | G2: 56 | H2: 57 | I2: 21617 | J2: 21618 | K2: 21619 | L2: EG.5.1 | M2: NTD | N2: 44 | O2: =COUNTIF(L:L,L2) -> 44 | P2: =COUNTIF(E:E,E2) -> 6 | Q2: =COUNTIF(A:A,A2) -> 6 | R2: =IF(P2>1,0,1) -> 0 | T2: C56T | U2: EG.5.1 | V2: 44 | W2: EG.5.1 | X2: C56T | Y2: EG.5.1 | AA2: 44 | AB2: EG.5.1 | AD2: spike_A27S, spike_D405N, spike_D614G, spike_D796Y, spike_E484A, spike_F456L, spike_F486P, spike_F490S, spike_G142D, spike_G252V, spike_G339H, spike_G446S, spike_H146Q, spike_H655Y, spike_K417N, spike_L24del, spike_L368I, spike_N440K, spike_N460K, spike_N501Y, spike_N679K, spike_N764K, spike_N969K, spike_P25del, spike_P26del, spike_P681H, spike_Q52H, spike_Q183E, spike_Q498R, spike_Q954H, spike_R346T, spike_R408S, spike_S371F, spike_S373P, spike_S375F, spike_S477N, spike_T19I, spike_T376A, spike_T478K, spike_V83A, spike_V213E, spike_V445P, spike_Y144del, spike_Y505H | AE2: C56T | AF2: T71- | AG2: A72- | AH2: C73- | AI2: C74- | AJ2: C75- | AK2: C76- | AL2: C77- | AM2: T78- | AN2: G79- | AO2: G156T | AP2: T248C | AQ2: G425A | AR2: T430- | AS2: A431- | AT2: T432- | AU2: C438A | AV2: C547G | AW2: T638A | AX2: G755T | AY2: G1015C | AZ2: G1016A | BA2: G1037C | BB2: C1102A | BC2: C1112T | BD2: T1117C | BE2: C1124T | BF2: A1126G | BG2: G1213A | BH2: A1224C | BI2: G1251T | BJ2: T1320G | BK2: G1333C | BL2: T1334C | BM2: G1336A | BN2: T1368A | BO2: T1380G | BP2: G1430A | BQ2: C1433A | BR2: A1451C | BS2: T1456C | BT2: T1457C | BU2: T1469C | BV2: A1493G | BW2: A1501T | BX2: T1513C | BY2: A1841G | BZ2: C1963T | CA2: T2037G | CB2: C2042A | CC2: C2292A | CD2: G2386T | CE2: A2862T | CF2: T2907A | CG2: C3438T
A3: L24- | B3: - | C3: EG.5.1 | D3: EG.5.1 | E3: 24 | F3: 70 | G3: 71 | H3: 72 | I3: 21632 | J3: 21633 | K3: 21634 | L3: EG.5.1 | M3: NTD | N3: 44 | O3: =COUNTIF(L:L,L3) -> 44 | P3: =COUNTIF(E:E,E3) -> 6 | Q3: =COUNTIF(A:A,A3) -> 6 | R3: =IF(P3>1,0,1) -> 0 | T3: T71- | U3: EG.5.1 | V3: 44 | W3: EG.5.1 | X3: T71- | Y3: EG.5.1 | AA3: 45 | AB3: BA.2.86 | AD3: Spike_A27S, Spike_A264D, Spike_A570V, Spike_D405N, Spike_D614G, Spike_D796Y, Spike_E484K, Spike_E554K, Spike_F157S, Spike_F486P, Spike_G142D, Spike_G339H, Spike_G446S, Spike_H69del, Spike_H245N, Spike_H655Y, Spike_I332V, Spike_K356T, Spike_K417N, Spike_L24del, Spike_L212I, Spike_L216F, Spike_L452W, Spike_N211del, Spike_N440K, Spike_N450D, Spike_N460K, Spike_N481K, Spike_N501Y, Spike_N679K, Spike_N764K, Spike_N969K, Spike_P25del, Spike_P26del, Spike_P621S, Spike_P681R, Spike_P1143L, Spike_Q498R, Spike_Q954H, Spike_R21T, Spike_R158G, Spike_R403K, Spike_R408S, Spike_S50L, Spike_S371F, Spike_S373P, Spike_S375F, Spike_S477N, Spike_S939F, Spike_T19I, Spike_T376A, Spike_T478E, Spike_V70del, Spike_V127F, Spike_V213G, Spike_V445H, Spike_V483del, Spike_Y144del, Spike_Y505H | AE3: C56T | AF3: C60T | AG3: G62C | AH3: T71- | AI3: A72- | AJ3: C73- | AK3: C74- | AL3: C75- | AM3: C76- | AN3: C77- | AO3: T78- | AP3: G79- | AQ3: C149T | AR3: T203- | AS3: A204- | AT3: C205- | AU3: A206- | AV3: T207- | AW3: G208- | AX3: G379T | AY3: G425A | AZ3: T430- | BA3: A431- | BB3: T432- | BC3: T470C | BD3: C471A | BE3: A472G | BF3: A632- | BG3: T633- | BH3: T634- | BI3: T638G | BJ3: C646T | BK3: C733A | BL3: C791A | BM3: A994G | BN3: G1015C | BO3: G1016A | BP3: A1067C | BQ3: C1112T | BR3: T1117C | BS3: C1124T | BT3: A1126G | BU3: G1208A | BV3: G1213A | BW3: A1224C | BX3: G1251T | BY3: T1320G | BZ3: G1333C | CA3: T1334A | CB3: G1336A | CC3: A1348G | CD3: C1354T | CE3: T1355G | CF3: T1380A | CG3: G1430A | CH3: A1432G | CI3: C1433A | CJ3: T1443A | CK3: G1447A | CL3: T1448- | CM3: T1449- | CN3: G1450- | CO3: T1456C | CP3: T1457C | CQ3: A1493G | CR3: A1501T | CS3: T1513C | CT3: G1660A | CU3: C1709T | CV3: A1841G | CW3: C1861T | CX3: C1963T | CY3: T2037G | CZ3: C2042G | DA3: C2292A | DB3: G2386T | DC3: C2816T | DD3: A2862T | DE3: T2907A | DF3: C3428T | DG3: C3438T | DH3: C3645T
A4: P25- | B4: - | C4: EG.5.1 | D4: EG.5.1 | E4: 25 | F4: 73 | G4: 74 | H4: 75 | I4: 21635 | J4: 21636 | K4: 21637 | L4: EG.5.1 | M4: NTD | N4: 44 | O4: =COUNTIF(L:L,L4) -> 44 | P4: =COUNTIF(E:E,E4) -> 6 | Q4: =COUNTIF(A:A,A4) -> 6 | R4: =IF(P4>1,0,1) -> 0 | T4: A72- | U4: EG.5.1 | V4: 44 | W4: EG.5.1 | X4: A72- | Y4: EG.5.1 | AA4: 48 | AB4: JN.1 | AD4: Spike_A27S, Spike_A264D, Spike_A570V, Spike_D405N, Spike_D614G, Spike_D796Y, Spike_E484K, Spike_E554K, Spike_F157S, Spike_F486P, Spike_G142D, Spike_G339H, Spike_G446S, Spike_H69del, Spike_H245N, Spike_H655Y, Spike_I332V, Spike_K356T, Spike_K417N, Spike_L24del, Spike_L212I, Spike_L216F, Spike_L452W, Spike_L455S, Spike_N211del, Spike_N440K, Spike_N450D, Spike_N460K, Spike_N481K, Spike_N501Y, Spike_N679K, Spike_N764K, Spike_N969K, Spike_P25del, Spike_P26del, Spike_P621S, Spike_P681R, Spike_P1143L, Spike_Q498R, Spike_Q954H, Spike_R21T, Spike_R158G, Spike_R403K, Spike_R408S, Spike_S50L, Spike_S371F, Spike_S373P, Spike_S375F, Spike_S477N, Spike_S939F, Spike_T19I, Spike_T376A, Spike_T478K, Spike_V70del, Spike_V127F, Spike_V213G, Spike_V445H, Spike_V483del, Spike_Y144del, Spike_Y505H | AE4: C56T | AF4: C60T | AG4: G62C | AH4: T71- | AI4: A72- | AJ4: C73- | AK4: C74- | AL4: C75- | AM4: C76- | AN4: C77- | AO4: T78- | AP4: G79- | AQ4: C149T | AR4: T203- | AS4: A204- | AT4: C205- | AU4: A206- | AV4: T207- | AW4: G208- | AX4: G379T | AY4: G425A | AZ4: T430- | BA4: A431- | BB4: T432- | BC4: T470C | BD4: C471A | BE4: A472G | BF4: A632- | BG4: T633- | BH4: T634- | BI4: T638G | BJ4: C646T | BK4: C733A | BL4: C791A | BM4: A994G | BN4: G1015C | BO4: G1016A | BP4: A1067C | BQ4: C1112T | BR4: T1117C | BS4: C1124T | BT4: A1126G | BU4: G1208A | BV4: G1213A | BW4: A1224C | BX4: G1251T | BY4: T1320G | BZ4: G1333C | CA4: T1334A | CB4: G1336A | CC4: A1348G | CD4: C1354T | CE4: T1355G | CF4: T1364C | CG4: T1380A | CH4: G1430A | CI4: C1433A | CJ4: T1443A | CK4: G1447A | CL4: T1448- | CM4: T1449- | CN4: G1450- | CO4: T1456C | CP4: T1457C | CQ4: A1493G | CR4: A1501T | CS4: T1513C | CT4: G1660A | CU4: C1709T | CV4: A1841G | CW4: C1861T | CX4: C1963T | CY4: T2037G | CZ4: C2042G | DA4: C2292A | DB4: G2386T | DC4: C2816T | DD4: A2862T | DE4: T2907A | DF4: C3428T | DG4: C3645T
A5: P26- | B5: - | C5: EG.5.1 | D5: EG.5.1 | E5: 26 | F5: 76 | G5: 77 | H5: 78 | I5: 21638 | J5: 21639 | K5: 21640 | L5: EG.5.1 | M5: NTD | N5: 44 | O5: =COUNTIF(L:L,L5) -> 44 | P5: =COUNTIF(E:E,E5) -> 6 | Q5: =COUNTIF(A:A,A5) -> 6 | R5: =IF(P5>1,0,1) -> 0 | T5: C73- | U5: EG.5.1 | V5: 44 | W5: EG.5.1 | X5: C73- | Y5: EG.5.1 | AA5: 48 | AB5: HK.3 | AD5: Spike_A27S, Spike_D405N, Spike_D614G, Spike_D796Y, Spike_E484A, Spike_F456L, Spike_F486P, Spike_F490S, Spike_G142D, Spike_G252V, Spike_G339H, Spike_G446S, Spike_H146Q, Spike_H655Y, Spike_K417N, Spike_L24del, Spike_L368I, Spike_L455F, Spike_N440K, Spike_N460K, Spike_N501Y, Spike_N679K, Spike_N764K, Spike_N969K, Spike_P25del, Spike_P26del, Spike_P681H, Spike_Q52H, Spike_Q183E, Spike_Q498R, Spike_Q954H, Spike_R346T, Spike_R408S, Spike_S371F, Spike_S373P, Spike_S375F, Spike_S477N, Spike_T19I, Spike_T376A, Spike_T478K, Spike_V83A, Spike_V213E, Spike_V445P, Spike_Y144del, Spike_Y505H | AE5: C56T | AF5: T71- | AG5: A72- | AH5: C73- | AI5: C74- | AJ5: C75- | AK5: C76- | AL5: C77- | AM5: T78- | AN5: G79- | AO5: G156T | AP5: T248C | AQ5: G425A | AR5: T430- | AS5: A431- | AT5: T432- | AU5: C438A | AV5: C547G | AW5: T638A | AX5: G755T | AY5: G1015C | AZ5: G1016A | BA5: G1037C | BB5: C1102A | BC5: C1112T | BD5: T1117C | BE5: C1124T | BF5: A1126G | BG5: G1213A | BH5: A1224C | BI5: G1251T | BJ5: T1320G | BK5: G1333C | BL5: T1334C | BM5: G1336A | BN5: G1365T | BO5: T1368A | BP5: T1380G | BQ5: G1430A | BR5: C1433A | BS5: A1451C | BT5: T1456C | BU5: T1457C | BV5: T1469C | BW5: A1493G | BX5: A1501T | BY5: T1513C | BZ5: A1841G | CA5: C1963T | CB5: T2037G | CC5: C2042A | CD5: C2292A | CE5: G2386T | CF5: A2862T | CG5: T2907A | CH5: C3438T
A6: A27S | B6: S | C6: EG.5.1 | D6: EG.5.1 | E6: 27 | F6: 79 | G6: 80 | H6: 81 | I6: 21641 | J6: 21642 | K6: 21643 | L6: EG.5.1 | M6: NTD | N6: 44 | O6: =COUNTIF(L:L,L6) -> 44 | P6: =COUNTIF(E:E,E6) -> 6 | Q6: =COUNTIF(A:A,A6) -> 6 | R6: =IF(P6>1,0,1) -> 0 | T6: C74- | U6: EG.5.1 | V6: 44 | W6: EG.5.1 | X6: C74- | Y6: EG.5.1 | AA6: 52 | AB6: KP.2 | AD6: Spike_A27S, Spike_A264D, Spike_A570V, Spike_D405N, Spike_D614G, Spike_D796Y, Spike_E484K, Spike_E554K, Spike_F157S, Spike_F456L, Spike_F486P, Spike_G142D, Spike_G339H, Spike_G446S, Spike_H69del, Spike_H245N, Spike_H655Y, Spike_I332V, Spike_K356T, Spike_K417N, Spike_L24del, Spike_L212I, Spike_L216F, Spike_L452W, Spike_L455S, Spike_N211del, Spike_N440K, Spike_N450D, Spike_N460K, Spike_N481K, Spike_N501Y, Spike_N679K, Spike_N764K, Spike_N969K, Spike_P25del, Spike_P26del, Spike_P621S, Spike_P681R, Spike_P1143L, Spike_Q498R, Spike_Q954H, Spike_R21T, Spike_R158G, Spike_R346T, Spike_R403K, Spike_R408S, Spike_S50L, Spike_S371F, Spike_S373P, Spike_S375F, Spike_S477N, Spike_S939F, Spike_T19I, Spike_T376A, Spike_T478K, Spike_V70del, Spike_V127F, Spike_V213G, Spike_V445H, Spike_V483del, Spike_V1104L, Spike_Y144del, Spike_Y505H | AE6: C56T | AF6: C60T | AG6: G62C | AH6: T71- | AI6: A72- | AJ6: C73- | AK6: C74- | AL6: C75- | AM6: C76- | AN6: C77- | AO6: T78- | AP6: G79- | AQ6: C149T | AR6: T203- | AS6: A204- | AT6: C205- | AU6: A206- | AV6: T207- | AW6: G208- | AX6: G379T | AY6: G425A | AZ6: T430- | BA6: A431- | BB6: T432- | BC6: T470C | BD6: C471A | BE6: A472G | BF6: A632- | BG6: T633- | BH6: T634- | BI6: T638G | BJ6: C646T | BK6: C733A | BL6: C791A | BM6: A994G | BN6: G1015C | BO6: G1016A | BP6: G1037C | BQ6: A1067C | BR6: C1112T | BS6: T1117C | BT6: C1124T | BU6: A1126G | BV6: G1208A | BW6: G1213A | BX6: A1224C | BY6: G1251T | BZ6: T1320G | CA6: G1333C | CB6: T1334A | CC6: G1336A | CD6: A1348G | CE6: C1354T | CF6: T1355G | CG6: T1364C | CH6: T1366C | CI6: T1380A | CJ6: G1430A | CK6: C1433A | CL6: T1443A | CM6: G1447A | CN6: T1448- | CO6: T1449- | CP6: G1450- | CQ6: T1456C | CR6: T1457C | CS6: A1493G | CT6: A1501T | CU6: T1513C | CV6: G1660A | CW6: C1709T | CX6: A1841G | CY6: C1861T | CZ6: C1963T | DA6: T2037G | DB6: C2042G | DC6: C2292A | DD6: G2386T | DE6: C2816T | DF6: A2862T | DG6: T2907A | DH6: G3310T | DI6: C3428T | DJ6: C3438T | DK6: C3645T
A7: Q52H | B7: H | C7: EG.5.1 | D7: EG.5.1 | E7: 52 | F7: 154 | G7: 155 | H7: 156 | I7: 21716 | J7: 21717 | K7: 21718 | L7: EG.5.1 | M7: NTD | N7: 44 | O7: =COUNTIF(L:L,L7) -> 44 | P7: =COUNTIF(E:E,E7) -> 2 | Q7: =COUNTIF(A:A,A7) -> 2 | R7: =IF(P7>1,0,1) -> 0 | T7: C75- | U7: EG.5.1 | V7: 44 | W7: EG.5.1 | X7: C75- | Y7: EG.5.1 | AA7: 53 | AB7: KP.3 | AD7: Spike_A27S, Spike_A264D, Spike_A570V, Spike_D405N, Spike_D614G, Spike_D796Y, Spike_E484K, Spike_E554K, Spike_F157S, Spike_F456L, Spike_F486P, Spike_G142D, Spike_G339H, Spike_G446S, Spike_H69del, Spike_H245N, Spike_H655Y, Spike_I332V, Spike_K356T, Spike_K417N, Spike_L24del, Spike_L212I, Spike_L216F, Spike_L452W, Spike_L455S, Spike_N211del, Spike_N440K, Spike_N450D, Spike_N460K, Spike_N481K, Spike_N501Y, Spike_N679K, Spike_N764K, Spike_N969K, Spike_P25del, Spike_P26del, Spike_P621S, Spike_P681R, Spike_P1143L, Spike_Q493E, Spike_Q498R, Spike_Q954H, Spike_R21T, Spike_R158G, Spike_R403K, Spike_R408S, Spike_S50L, Spike_S371F, Spike_S373P, Spike_S375F, Spike_S477N, Spike_S939F, Spike_T19I, Spike_T376A, Spike_T478K, Spike_V70del, Spike_V127F, Spike_V213G, Spike_V445H, Spike_V483del, Spike_V1104L, Spike_Y144del, Spike_Y505H | AE7: C56T | AF7: C60T | AG7: G62C | AH7: T71- | AI7: A72- | AJ7: C73- | AK7: C74- | AL7: C75- | AM7: C76- | AN7: C77- | AO7: T78- | AP7: G79- | AQ7: C149T | AR7: T203- | AS7: A204- | AT7: C205- | AU7: A206- | AV7: T207- | AW7: G208- | AX7: G379T | AY7: G425A | AZ7: T430- | BA7: A431- | BB7: T432- | BC7: T470C | BD7: C471A | BE7: A472G | BF7: A632- | BG7: T633- | BH7: T634- | BI7: T638G | BJ7: C646T | BK7: C733A | BL7: C791A | BM7: A994G | BN7: G1015C | BO7: G1016A | BP7: A1067C | BQ7: C1112T | BR7: T1117C | BS7: C1124T | BT7: A1126G | BU7: G1208A | BV7: G1213A | BW7: A1224C | BX7: G1251T | BY7: T1320G | BZ7: G1333C | CA7: T1334A | CB7: G1336A | CC7: A1348G | CD7: C1354T | CE7: T1355G | CF7: T1364C | CG7: T1366C | CH7: T1380A | CI7: G1430A | CJ7: C1433A | CK7: T1443A | CL7: G1447A | CM7: T1448- | CN7: T1449- | CO7: G1450- | CP7: T1456C | CQ7: T1457C | CR7: C1477G | CS7: A1493G | CT7: A1501T | CU7: T1513C | CV7: G1660A | CW7: C1709T | CX7: A1841G | CY7: C1861T | CZ7: C1963T | DA7: T2037G | DB7: C2042G | DC7: C2292A | DD7: G2386T | DE7: C2816T | DF7: A2862T | DG7: T2907A | DH7: G3310T | DI7: C3428T | DJ7: C3438T | DK7: C3645T
A8: V83A | B8: A | C8: EG.5.1 | D8: EG.5.1 | E8: 83 | F8: 247 | G8: 248 | H8: 249 | I8: 21809 | J8: 21810 | K8: 21811 | L8: EG.5.1 | M8: NTD | N8: 44 | O8: =COUNTIF(L:L,L8) -> 44 | P8: =COUNTIF(E:E,E8) -> 2 | Q8: =COUNTIF(A:A,A8) -> 2 | R8: =IF(P8>1,0,1) -> 0 | T8: C76- | U8: EG.5.1 | V8: 44 | W8: EG.5.1 | X8: C76- | Y8: EG.5.1
A9: G142D | B9: D | C9: EG.5.1 | D9: EG.5.1 | E9: 142 | F9: 424 | G9: 425 | H9: 426 | I9: 21986 | J9: 21987 | K9: 21988 | L9: EG.5.1 | M9: NTD | N9: 44 | O9: =COUNTIF(L:L,L9) -> 44 | P9: =COUNTIF(E:E,E9) -> 6 | Q9: =COUNTIF(A:A,A9) -> 6 | R9: =IF(P9>1,0,1) -> 0 | T9: C77- | U9: EG.5.1 | V9: 44 | W9: EG.5.1 | X9: C77- | Y9: EG.5.1
A10: Y144- | B10: - | C10: EG.5.1 | D10: EG.5.1 | E10: 144 | F10: 430 | G10: 431 | H10: 432 | I10: 21992 | J10: 21993 | K10: 21994 | L10: EG.5.1 | M10: NTD | N10: 44 | O10: =COUNTIF(L:L,L10) -> 44 | P10: =COUNTIF(E:E,E10) -> 6 | Q10: =COUNTIF(A:A,A10) -> 6 | R10: =IF(P10>1,0,1) -> 0 | T10: T78- | U10: EG.5.1 | V10: 44 | W10: EG.5.1 | X10: T78- | Y10: EG.5.1
A11: H146Q | B11: Q | C11: EG.5.1 | D11: EG.5.1 | E11: 146 | F11: 436 | G11: 437 | H11: 438 | I11: 21998 | J11: 21999 | K11: 22000 | L11: EG.5.1 | M11: NTD | N11: 44 | O11: =COUNTIF(L:L,L11) -> 44 | P11: =COUNTIF(E:E,E11) -> 2 | Q11: =COUNTIF(A:A,A11) -> 2 | R11: =IF(P11>1,0,1) -> 0 | T11: G79- | U11: EG.5.1 | V11: 44 | W11: EG.5.1 | X11: G79- | Y11: EG.5.1
A12: Q183E | B12: E | C12: EG.5.1 | D12: EG.5.1 | E12: 183 | F12: 547 | G12: 548 | H12: 549 | I12: 22109 | J12: 22110 | K12: 22111 | L12: EG.5.1 | M12: NTD | N12: 44 | O12: =COUNTIF(L:L,L12) -> 44 | P12: =COUNTIF(E:E,E12) -> 2 | Q12: =COUNTIF(A:A,A12) -> 2 | R12: =IF(P12>1,0,1) -> 0 | T12: G156T | U12: EG.5.1 | V12: 44 | W12: EG.5.1 | X12: G156T | Y12: EG.5.1
A13: V213E | B13: E | C13: EG.5.1 | D13: EG.5.1 | E13: 213 | F13: 637 | G13: 638 | H13: 639 | I13: 22199 | J13: 22200 | K13: 22201 | L13: EG.5.1 | M13: NTD | N13: 44 | O13: =COUNTIF(L:L,L13) -> 44 | P13: =COUNTIF(E:E,E13) -> 6 | Q13: =COUNTIF(A:A,A13) -> 2 | R13: =IF(P13>1,0,1) -> 0 | T13: T248C | U13: EG.5.1 | V13: 44 | W13: EG.5.1 | X13: T248C | Y13: EG.5.1
A14: G252V | B14: V | C14: EG.5.1 | D14: EG.5.1 | E14: 252 | F14: 754 | G14: 755 | H14: 756 | I14: 22316 | J14: 22317 | K14: 22318 | L14: EG.5.1 | M14: NTD | N14: 44 | O14: =COUNTIF(L:L,L14) -> 44 | P14: =COUNTIF(E:E,E14) -> 2 | Q14: =COUNTIF(A:A,A14) -> 2 | R14: =IF(P14>1,0,1) -> 0 | T14: G425A | U14: EG.5.1 | V14: 44 | W14: EG.5.1 | X14: G425A | Y14: EG.5.1
A15: G339H | B15: H | C15: EG.5.1 | D15: EG.5.1 | E15: 339 | F15: 1015 | G15: 1016 | H15: 1017 | I15: 22577 | J15: 22578 | K15: 22579 | L15: EG.5.1 | M15: RBD | N15: 44 | O15: =COUNTIF(L:L,L15) -> 44 | P15: =COUNTIF(E:E,E15) -> 6 | Q15: =COUNTIF(A:A,A15) -> 6 | R15: =IF(P15>1,0,1) -> 0 | T15: T430- | U15: EG.5.1 | V15: 44 | W15: EG.5.1 | X15: T430- | Y15: EG.5.1
A16: R346T | B16: T | C16: EG.5.1 | D16: EG.5.1 | E16: 346 | F16: 1036 | G16: 1037 | H16: 1038 | I16: 22598 | J16: 22599 | K16: 22600 | L16: EG.5.1 | M16: RBD | N16: 44 | O16: =COUNTIF(L:L,L16) -> 44 | P16: =COUNTIF(E:E,E16) -> 3 | Q16: =COUNTIF(A:A,A16) -> 3 | R16: =IF(P16>1,0,1) -> 0 | T16: A431- | U16: EG.5.1 | V16: 44 | W16: EG.5.1 | X16: A431- | Y16: EG.5.1
A17: L368I | B17: I | C17: EG.5.1 | D17: EG.5.1 | E17: 368 | F17: 1102 | G17: 1103 | H17: 1104 | I17: 22664 | J17: 22665 | K17: 22666 | L17: EG.5.1 | M17: RBD | N17: 44 | O17: =COUNTIF(L:L,L17) -> 44 | P17: =COUNTIF(E:E,E17) -> 2 | Q17: =COUNTIF(A:A,A17) -> 2 | R17: =IF(P17>1,0,1) -> 0 | T17: T432- | U17: EG.5.1 | V17: 44 | W17: EG.5.1 | X17: T432- | Y17: EG.5.1
A18: S371F | B18: F | C18: EG.5.1 | D18: EG.5.1 | E18: 371 | F18: 1111 | G18: 1112 | H18: 1113 | I18: 22673 | J18: 22674 | K18: 22675 | L18: EG.5.1 | M18: RBD | N18: 44 | O18: =COUNTIF(L:L,L18) -> 44 | P18: =COUNTIF(E:E,E18) -> 6 | Q18: =COUNTIF(A:A,A18) -> 6 | R18: =IF(P18>1,0,1) -> 0 | T18: C438A | U18: EG.5.1 | V18: 44 | W18: EG.5.1 | X18: C438A | Y18: EG.5.1
A19: S373P | B19: P | C19: EG.5.1 | D19: EG.5.1 | E19: 373 | F19: 1117 | G19: 1118 | H19: 1119 | I19: 22679 | J19: 22680 | K19: 22681 | L19: EG.5.1 | M19: RBD | N19: 44 | O19: =COUNTIF(L:L,L19) -> 44 | P19: =COUNTIF(E:E,E19) -> 6 | Q19: =COUNTIF(A:A,A19) -> 6 | R19: =IF(P19>1,0,1) -> 0 | T19: C547G | U19: EG.5.1 | V19: 44 | W19: EG.5.1 | X19: C547G | Y19: EG.5.1
... A335: P1143L | B335: L | C335: KP.3 | D335: KP.3 | E335: 1143 | F335: 3427 | G335: 3428 | H335: 3429 | I335: 24989 | J335: 24990 | K335: 24991 | L335: KP.3 | M335: S2 | N335: 53 | O335: =COUNTIF(L:L,L335) -> 63 | P335: =COUNTIF(E:E,E335) -> 4 | Q335: =COUNTIF(A:A,A335) -> 4 | R335: =IF(P335>1,0,1) -> 0 | T335: T1443A | U335: KP.2 | V335: 52 | W335: KP.2 | X335: T1443A | Y335: KP.2
T336: G1447A | U336: KP.2 | V336: 52 | W336: KP.2 | X336: G1447A | Y336: KP.2
T337: T1448- | U337: KP.2 | V337: 52 | W337: KP.2 | X337: T1448- | Y337: KP.2
T338: T1449- | U338: KP.2 | V338: 52 | W338: KP.2 | X338: T1449- | Y338: KP.2
T339: G1450- | U339: KP.2 | V339: 52 | W339: KP.2 | X339: G1450- | Y339: KP.2
T340: T1456C | U340: KP.2 | V340: 52 | W340: KP.2 | X340: T1456C | Y340: KP.2
T341: T1457C | U341: KP.2 | V341: 52 | W341: KP.2 | X341: T1457C | Y341: KP.2
T342: A1493G | U342: KP.2 | V342: 52 | W342: KP.2 | X342: A1493G | Y342: KP.2
T343: A1501T | U343: KP.2 | V343: 52 | W343: KP.2 | X343: A1501T | Y343: KP.2
T344: T1513C | U344: KP.2 | V344: 52 | W344: KP.2 | X344: T1513C | Y344: KP.2
T345: G1660A | U345: KP.2 | V345: 52 | W345: KP.2 | X345: G1660A | Y345: KP.2
T346: C1709T | U346: KP.2 | V346: 52 | W346: KP.2 | X346: C1709T | Y346: KP.2
T347: A1841G | U347: KP.2 | V347: 52 | W347: KP.2 | X347: A1841G | Y347: KP.2
... T445: C3645T | U445: KP.3 | V445: 53 | W445: KP.3 | X445: C3645T | Y445: KP.3
